Workbook

Sheet 2022년 누적시트
A1: 번호 | B1: 소속기관 | C1: 소속부서(복사) | D1: 소속부 | E1: 소속부서 | F1: 담당자 | G1: 보도관련 | H1: 제 목 | I1: 보도매체 | J1: 게재일 | K1: 면 | L1: 구분 1 | M1: 구분 2(점수) | N1: 스크랩일
A2: 1 | B2: 8_국립축산과학원 | C2: =E2 -> 2_낙농과 | D2: =IFERROR(VLOOKUP(C2,소속부서!$A$2:$B$20,2,FALSE), "") -> 2_축산자원개발부 | E2: 2_낙농과 | F2: 박성민 | G2: 즉시52 | H2: 농진청·기업 개발 로봇착유기 대만 수출...세계시장 진출 발판 | I2: 연합뉴스 | J2: 45875 | L2: =IFERROR(VLOOKUP(I2,보도매체!$A:$C,2,FALSE), "") -> 07_중앙일간지 | M2: =IFERROR(VLOOKUP(I2,보도매체!$A:$C,3,FALSE), "") -> 5 | N2: 45876
A3: 2 | B3: 8_국립축산과학원 | C3: =E3 -> 2_낙농과 | D3: =IFERROR(VLOOKUP(C3,소속부서!$A$2:$B$20,2,FALSE), "") -> 2_축산자원개발부 | E3: 2_낙농과 | F3: 박성민 | G3: 즉시52 | H3: 농진청, ‘K-로봇착유기’ 7대 대만 수출...“국산 기술 경쟁력 입증” | I3: 아시아투데이 | J3: 45875 | L3: =IFERROR(VLOOKUP(I3,보도매체!$A:$C,2,FALSE), "") -> 07_중앙일간지 | M3: =IFERROR(VLOOKUP(I3,보도매체!$A:$C,3,FALSE), "") -> 5 | N3: 45876
A4: 3 | B4: 8_국립축산과학원 | C4: =E4 -> 2_낙농과 | D4: =IFERROR(VLOOKUP(C4,소속부서!$A$2:$B$20,2,FALSE), "") -> 2_축산자원개발부 | E4: 2_낙농과 | F4: 박성민 | G4: 즉시52 | H4: 농촌진흥청, 로봇 착유기 대만 수출...민간기업과 공동 개발 ‘데어리봇’ | I4: 부산일보 | J4: 45875 | L4: =IFERROR(VLOOKUP(I4,보도매체!$A:$C,2,FALSE), "") -> 09_지방일간지 | M4: =IFERROR(VLOOKUP(I4,보도매체!$A:$C,3,FALSE), "") -> 1.5 | N4: 45876
A5: 4 | B5: 8_국립축산과학원 | C5: =E5 -> 2_낙농과 | D5: =IFERROR(VLOOKUP(C5,소속부서!$A$2:$B$20,2,FALSE), "") -> 2_축산자원개발부 | E5: 2_낙농과 | F5: 박성민 | G5: 즉시52 | H5: 국산 로봇착유기 7대 대만 수출...낙농시장 교두보 확보 | I5: 뉴스1 | J5: 45875 | L5: =IFERROR(VLOOKUP(I5,보도매체!$A:$C,2,FALSE), "") -> 07_중앙일간지 | M5: =IFERROR(VLOOKUP(I5,보도매체!$A:$C,3,FALSE), "") -> 5 | N5: 45876
A6: 5 | B6: 8_국립축산과학원 | C6: =E6 -> 2_낙농과 | D6: =IFERROR(VLOOKUP(C6,소속부서!$A$2:$B$20,2,FALSE), "") -> 2_축산자원개발부 | E6: 2_낙농과 | F6: 박성민 | G6: 즉시52 | H6: 국산 로봇착유기 대만 수출 기념식 | I6: 뉴시스 | J6: 45875 | L6: =IFERROR(VLOOKUP(I6,보도매체!$A:$C,2,FALSE), "") -> 07_중앙일간지 | M6: =IFERROR(VLOOKUP(I6,보도매체!$A:$C,3,FALSE), "") -> 5 | N6: 45876
A7: 6 | B7: 8_국립축산과학원 | C7: =E7 -> 2_낙농과 | D7: =IFERROR(VLOOKUP(C7,소속부서!$A$2:$B$20,2,FALSE), "") -> 2_축산자원개발부 | E7: 2_낙농과 | F7: 박성민 | G7: 즉시52 | H7: 국산 로봇착유기 대만 수출 | I7: 뉴시스 | J7: 45875 | L7: =IFERROR(VLOOKUP(I7,보도매체!$A:$C,2,FALSE), "") -> 07_중앙일간지 | M7: =IFERROR(VLOOKUP(I7,보도매체!$A:$C,3,FALSE), "") -> 5 | N7: 45876
A8: 7 | B8: 8_국립축산과학원 | C8: =E8 -> 1_가축개량평가과 | D8: =IFERROR(VLOOKUP(C8,소속부서!$A$2:$B$20,2,FALSE), "") -> 2_축산자원개발부 | E8: 1_가축개량평가과 | F8: 박미나 | H8: 최고의 한우 보증씨수소 탄생···경북도, 우수 유전능력 뽐내 | I8: 경상투데이 | J8: 45875 | K8: 3 | L8: =IFERROR(VLOOKUP(I8,보도매체!$A:$C,2,FALSE), "") -> 09_지방일간지 | M8: =IFERROR(VLOOKUP(I8,보도매체!$A:$C,3,FALSE), "") -> 1.5 | N8: 45876
A9: 8 | B9: 8_국립축산과학원 | C9: =E9 -> 1_가축개량평가과 | D9: =IFERROR(VLOOKUP(C9,소속부서!$A$2:$B$20,2,FALSE), "") -> 2_축산자원개발부 | E9: 1_가축개량평가과 | F9: 박미나 | H9: 경북축산기술 자체 생산 씨수소 ‘전국 1위’ 우뚝 | I9: 경안일보 | J9: 45875 | K9: 1 | L9: =IFERROR(VLOOKUP(I9,보도매체!$A:$C,2,FALSE), "") -> 09_지방일간지 | M9: =IFERROR(VLOOKUP(I9,보도매체!$A:$C,3,FALSE), "") -> 1.5 | N9: 45876
A10: 9 | B10: 8_국립축산과학원 | C10: =E10 -> 1_가축개량평가과 | D10: =IFERROR(VLOOKUP(C10,소속부서!$A$2:$B$20,2,FALSE), "") -> 2_축산자원개발부 | E10: 1_가축개량평가과 | F10: 박미나 | H10: 경북축산기술 자체 개발 한우 KPN1707, 보증씨수소 1위 선발 | I10: 경북일보 | J10: 45875 | K10: 11 | L10: =IFERROR(VLOOKUP(I10,보도매체!$A:$C,2,FALSE), "") -> 09_지방일간지 | M10: =IFERROR(VLOOKUP(I10,보도매체!$A:$C,3,FALSE), "") -> 1.5 | N10: 45876
A11: 10 | B11: 8_국립축산과학원 | C11: =E11 -> 1_가축개량평가과 | D11: =IFERROR(VLOOKUP(C11,소속부서!$A$2:$B$20,2,FALSE), "") -> 2_축산자원개발부 | E11: 1_가축개량평가과 | F11: 박미나 | H11: 경북도, 2025년 상반기 한우 보증씨수소 선발 시상 | I11: 대구경북일보 | J11: 45875 | K11: 1 | L11: =IFERROR(VLOOKUP(I11,보도매체!$A:$C,2,FALSE), "") -> 11_기타(지역주간지) | M11: =IFERROR(VLOOKUP(I11,보도매체!$A:$C,3,FALSE), "") -> 0.5 | N11: 45876
A12: 11 | B12: 8_국립축산과학원 | C12: =E12 -> 1_가축개량평가과 | D12: =IFERROR(VLOOKUP(C12,소속부서!$A$2:$B$20,2,FALSE), "") -> 2_축산자원개발부 | E12: 1_가축개량평가과 | F12: 박미나 | H12: 경북도, 한우 보증씨수소 개발능력 입증 | I12: 대경일보 | J12: 45875 | K12: 2 | L12: =IFERROR(VLOOKUP(I12,보도매체!$A:$C,2,FALSE), "") -> 09_지방일간지 | M12: =IFERROR(VLOOKUP(I12,보도매체!$A:$C,3,FALSE), "") -> 1.5 | N12: 45876
A13: 12 | B13: 8_국립축산과학원 | C13: =E13 -> 1_가축개량평가과 | D13: =IFERROR(VLOOKUP(C13,소속부서!$A$2:$B$20,2,FALSE), "") -> 2_축산자원개발부 | E13: 1_가축개량평가과 | F13: 박미나 | H13: 경북도, 상반기 한우 보증씨수소 선발 시상식 | I13: 세명일보 | J13: 45875 | K13: 2 | L13: =IFERROR(VLOOKUP(I13,보도매체!$A:$C,2,FALSE), "") -> 11_기타(지역주간지) | M13: =IFERROR(VLOOKUP(I13,보도매체!$A:$C,3,FALSE), "") -> 0.5 | N13: 45876
A14: 13 | B14: 8_국립축산과학원 | C14: =E14 -> 2_낙농과 | D14: =IFERROR(VLOOKUP(C14,소속부서!$A$2:$B$20,2,FALSE), "") -> 2_축산자원개발부 | E14: 2_낙농과 | F14: 박성민 | G14: 즉시52 | H14: ‘국산 로봇착유기’ 대만 수출 | I14: 팜앤마켓 | J14: 45875 | L14: =IFERROR(VLOOKUP(I14,보도매체!$A:$C,2,FALSE), "") -> 13_인터넷포털 | M14: =IFERROR(VLOOKUP(I14,보도매체!$A:$C,3,FALSE), "") -> 0.1 | N14: 45876
A15: 14 | B15: 8_국립축산과학원 | C15: =E15 -> 2_낙농과 | D15: =IFERROR(VLOOKUP(C15,소속부서!$A$2:$B$20,2,FALSE), "") -> 2_축산자원개발부 | E15: 2_낙농과 | F15: 박성민 | G15: 즉시52 | H15: ‘로봇착유기’ 대만 수출...맞춤형 기술 적용 | I15: 한국경제TV | J15: 45875 | L15: =IFERROR(VLOOKUP(I15,보도매체!$A:$C,2,FALSE), "") -> 13_인터넷포털 | M15: =IFERROR(VLOOKUP(I15,보도매체!$A:$C,3,FALSE), "") -> 0.1 | N15: 45876
A16: 15 | B16: 8_국립축산과학원 | C16: =E16 -> 4_조사료생산시스템과 | D16: =IFERROR(VLOOKUP(C16,소속부서!$A$2:$B$20,2,FALSE), "") -> 2_축산자원개발부 | E16: 4_조사료생산시스템과 | F16: 최보람 | G16: 즉시51 | H16: 창녕군, 사료피 신품종 현장 평가회 성황 | I16: 이뉴스투데이 | J16: 45875 | L16: =IFERROR(VLOOKUP(I16,보도매체!$A:$C,2,FALSE), "") -> 10_주간지 | M16: =IFERROR(VLOOKUP(I16,보도매체!$A:$C,3,FALSE), "") -> 1 | N16: 45876
A17: 16 | B17: 8_국립축산과학원 | C17: =E17 -> 2_낙농과 | D17: =IFERROR(VLOOKUP(C17,소속부서!$A$2:$B$20,2,FALSE), "") -> 2_축산자원개발부 | E17: 2_낙농과 | F17: 박성민 | G17: 즉시52 | H17: 농촌진흥청 공동 개발 ‘로봇착유기’ 타이완에 첫 수출···세계시장 진출 발판 | I17: KBS | J17: 45875 | L17: =IFERROR(VLOOKUP(I17,보도매체!$A:$C,2,FALSE), "") -> 01_TV-중앙 | M17: =IFERROR(VLOOKUP(I17,보도매체!$A:$C,3,FALSE), "") -> 8 | N17: 45876
A18: 17 | B18: 8_국립축산과학원 | C18: =E18 -> 4_조사료생산시스템과 | D18: =IFERROR(VLOOKUP(C18,소속부서!$A$2:$B$20,2,FALSE), "") -> 2_축산자원개발부 | E18: 4_조사료생산시스템과 | F18: 최보람 | G18: 즉시51 | H18: 창녕군, 사료피 신품종 ‘다온’ 현장 평가·수확 연시회 개최 | I18: 아시아경제 | J18: 45875 | L18: =IFERROR(VLOOKUP(I18,보도매체!$A:$C,2,FALSE), "") -> 07_중앙일간지 | M18: =IFERROR(VLOOKUP(I18,보도매체!$A:$C,3,FALSE), "") -> 5 | N18: 45876
A19: 18 | B19: 8_국립축산과학원 | C19: =E19 -> 2_낙농과 | D19: =IFERROR(VLOOKUP(C19,소속부서!$A$2:$B$20,2,FALSE), "") -> 2_축산자원개발부 | E19: 2_낙농과 | F19: 박성민 | G19: 즉시52 | H19: ‘국산 로봇착유기’ 대만 수출···세계 시장 진출 발판 | I19: 전북일보 | J19: 45875 | L19: =IFERROR(VLOOKUP(I19,보도매체!$A:$C,2,FALSE), "") -> 09_지방일간지 | M19: =IFERROR(VLOOKUP(I19,보도매체!$A:$C,3,FALSE), "") -> 1.5 | N19: 45876
A20: 19 | B20: 8_국립축산과학원 | C20: =E20 -> 4_조사료생산시스템과 | D20: =IFERROR(VLOOKUP(C20,소속부서!$A$2:$B$20,2,FALSE), "") -> 2_축산자원개발부 | E20: 4_조사료생산시스템과 | F20: 최보람 | G20: 즉시51 | H20: 창녕군, 고온다습한 여름철에도 강한 신품종 ‘다온’ 첫 선 | I20: 뉴스프리존 | J20: 45875 | L20: =IFERROR(VLOOKUP(I20,보도매체!$A:$C,2,FALSE), "") -> 13_인터넷포털 | M20: =IFERROR(VLOOKUP(I20,보도매체!$A:$C,3,FALSE), "") -> 0.1 | N20: 45876
A21: 20 | B21: 8_국립축산과학원 | C21: =E21 -> 2_낙농과 | D21: =IFERROR(VLOOKUP(C21,소속부서!$A$2:$B$20,2,FALSE), "") -> 2_축산자원개발부 | E21: 2_낙농과 | F21: 박성민 | G21: 즉시52 | H21: 농진청, 기업 개발 로봇착유기 ‘데어리봇’ 대만 수출 | I21: 포인트데일리 | J21: 45875 | L21: =IFERROR(VLOOKUP(I21,보도매체!$A:$C,2,FALSE), "") -> 13_인터넷포털 | M21: =IFERROR(VLOOKUP(I21,보도매체!$A:$C,3,FALSE), "") -> 0.1 | N21: 45876
A22: 21 | B22: 8_국립축산과학원 | C22: =E22 -> 4_조사료생산시스템과 | D22: =IFERROR(VLOOKUP(C22,소속부서!$A$2:$B$20,2,FALSE), "") -> 2_축산자원개발부 | E22: 4_조사료생산시스템과 | F22: 최보람 | G22: 즉시51 | H22: 창녕군, 사료피 신품종 ‘다온’ 현장 평가 및 수확 연시회 개최 | I22: 신아일보 | J22: 45875 | L22: =IFERROR(VLOOKUP(I22,보도매체!$A:$C,2,FALSE), "") -> 08_기타일간지 | M22: =IFERROR(VLOOKUP(I22,보도매체!$A:$C,3,FALSE), "") -> 2 | N22: 45876
A23: 22 | B23: 8_국립축산과학원 | C23: =E23 -> 4_조사료생산시스템과 | D23: =IFERROR(VLOOKUP(C23,소속부서!$A$2:$B$20,2,FALSE), "") -> 2_축산자원개발부 | E23: 4_조사료생산시스템과 | F23: 최보람 | G23: 즉시51 | H23: [창녕군 소식] 사료피 신품종 평가회-남지라이온스클럽 이웃돕기 성품 | I23: KPI뉴스 | J23: 45875 | L23: =IFERROR(VLOOKUP(I23,보도매체!$A:$C,2,FALSE), "") -> 13_인터넷포털 | M23: =IFERROR(VLOOKUP(I23,보도매체!$A:$C,3,FALSE), "") -> 0.1 | N23: 45876
A24: 23 | B24: 8_국립축산과학원 | C24: =E24 -> 2_낙농과 | D24: =IFERROR(VLOOKUP(C24,소속부서!$A$2:$B$20,2,FALSE), "") -> 2_축산자원개발부 | E24: 2_낙농과 | F24: 박성민 | G24: 즉시52 | H24: 국산 로봇착유기, 대만 첫 수출...아시아 낙농 시장 공략 | I24: 베타뉴스 | J24: 45875 | L24: =IFERROR(VLOOKUP(I24,보도매체!$A:$C,2,FALSE), "") -> 13_인터넷포털 | M24: =IFERROR(VLOOKUP(I24,보도매체!$A:$C,3,FALSE), "") -> 0.1 | N24: 45876
A25: 24 | B25: 8_국립축산과학원 | C25: =E25 -> 4_조사료생산시스템과 | D25: =IFERROR(VLOOKUP(C25,소속부서!$A$2:$B$20,2,FALSE), "") -> 2_축산자원개발부 | E25: 4_조사료생산시스템과 | F25: 최보람 | G25: 즉시51 | H25: 창녕군, 사료피 신품종 현장 평가회 성황리 개최 | I25: 경남도민신문 | J25: 45875 | L25: =IFERROR(VLOOKUP(I25,보도매체!$A:$C,2,FALSE), "") -> 09_지방일간지 | M25: =IFERROR(VLOOKUP(I25,보도매체!$A:$C,3,FALSE), "") -> 1.5 | N25: 45876
... A35: 34 | B35: 8_국립축산과학원 | C35: =E35 -> 4_조사료생산시스템과 | D35: =IFERROR(VLOOKUP(C35,소속부서!$A$2:$B$20,2,FALSE), "") -> 2_축산자원개발부 | E35: 4_조사료생산시스템과 | F35: 최보람 | G35: 즉시51 | H35: 창녕군, 사료피 신품종 ‘다온’ 등 현장 평가회 | I35: 뉴스메이커 | J35: 45876 | L35: =IFERROR(VLOOKUP(I35,보도매체!$A:$C,2,FALSE), "") -> 10_기타월간지 | M35: =IFERROR(VLOOKUP(I35,보도매체!$A:$C,3,FALSE), "") -> 1 | N35: 45876
A36: 35 | B36: 8_국립축산과학원 | C36: =#REF! -> #REF! | D36: 1_축산생명환경부 | E36: 3_축산푸드테크과 | F36: 강선문 | G36: 보도자료78 | H36: 복달임 음식으로 주목 받는 ‘염소 고기’...단백질·칼슘·비타민 풍부 | I36: 파이낸셜뉴스 | J36: 45876 | L36: =IFERROR(VLOOKUP(I36,[1]보도매체!$A:$C,2,FALSE), "") -> 07_중앙일간지 | M36: =IFERROR(VLOOKUP(I36,[1]보도매체!$A:$C,3,FALSE), "") -> 5 | N36: 45877
A37: 36 | B37: 8_국립축산과학원 | C37: =#REF! -> #REF! | D37: 1_축산생명환경부 | E37: 3_축산푸드테크과 | F37: 강선문 | G37: 보도자료78 | H37: 농촌진흥청 “여름철 기력회복엔 염소고기”...체력보강에 좋아 | I37: 부산일보 | J37: 45876 | L37: =IFERROR(VLOOKUP(I37,[1]보도매체!$A:$C,2,FALSE), "") -> 09_지방일간지 | M37: =IFERROR(VLOOKUP(I37,[1]보도매체!$A:$C,3,FALSE), "") -> 1.5 | N37: 45877
A38: 37 | B38: 8_국립축산과학원 | C38: =#REF! -> #REF! | D38: 1_축산생명환경부 | E38: 3_축산푸드테크과 | F38: 강선문 | G38: 보도자료78 | H38: 말복엔 ‘염소탕’ 드세요...농진청, 간편 조리법 소개 | I38: 뉴스핌 | J38: 45876 | L38: =IFERROR(VLOOKUP(I38,[1]보도매체!$A:$C,2,FALSE), "") -> 13_인터넷포털 | M38: =IFERROR(VLOOKUP(I38,[1]보도매체!$A:$C,3,FALSE), "") -> 0.1 | N38: 45877
A39: 38 | B39: 8_국립축산과학원 | C39: =#REF! -> #REF! | D39: 2_축산자원개발부 | E39: 2_낙농과 | F39: 박성민 | G39: 즉시52 | H39: [녹색] 국산 ‘로봇착유기’ 타이완 수출...세계 시장 진출 발판(종합뉴스) | I39: YTN | J39: 45876 | L39: =IFERROR(VLOOKUP(I39,[1]보도매체!$A:$C,2,FALSE), "") -> 02_TV-케이블중앙 | M39: =IFERROR(VLOOKUP(I39,[1]보도매체!$A:$C,3,FALSE), "") -> 4 | N39: 45877
A40: 39 | B40: 8_국립축산과학원 | C40: =#REF! -> #REF! | D40: 2_축산자원개발부 | E40: 2_낙농과 | F40: 박성민 | G40: 즉시52 | H40: [녹색] 국산 ‘로봇착유기’ 타이완 수출...세계 시장 진출 발판(YTN24) | I40: YTN | J40: 45876 | L40: =IFERROR(VLOOKUP(I40,[1]보도매체!$A:$C,2,FALSE), "") -> 02_TV-케이블중앙 | M40: =IFERROR(VLOOKUP(I40,[1]보도매체!$A:$C,3,FALSE), "") -> 4 | N40: 45877
A41: 40 | B41: 8_국립축산과학원 | C41: =#REF! -> #REF! | D41: 2_축산자원개발부 | E41: 2_낙농과 | F41: 박성민 | G41: 즉시52 | H41: “노동 시간 절반으로”··국산 ‘로봇 착유기’ 수출 | I41: MBC-TV | J41: 45876 | L41: =IFERROR(VLOOKUP(I41,[1]보도매체!$A:$C,2,FALSE), "") -> 02_TV-지방 | M41: =IFERROR(VLOOKUP(I41,[1]보도매체!$A:$C,3,FALSE), "") -> 4 | N41: 45877
A42: 41 | B42: 8_국립축산과학원 | C42: =#REF! -> #REF! | D42: 2_축산자원개발부 | E42: 2_낙농과 | F42: 박성민 | G42: 즉시52 | H42: 국산 로봇착유기 ‘데어리봇’ 세계 시장 진출 | I42: 전북타임스 | J42: 45876 | K42: 4 | L42: =IFERROR(VLOOKUP(I42,[1]보도매체!$A:$C,2,FALSE), "") -> 09_지방일간지 | M42: =IFERROR(VLOOKUP(I42,[1]보도매체!$A:$C,3,FALSE), "") -> 1.5 | N42: 45877
A43: 42 | B43: 8_국립축산과학원 | C43: =#REF! -> #REF! | D43: 2_축산자원개발부 | E43: 2_낙농과 | F43: 박성민 | G43: 즉시52 | H43: ‘국산 로봇착유기’ 대만 수출길 올라 | I43: 전북연합신문 | J43: 45876 | K43: 5 | L43: =IFERROR(VLOOKUP(I43,[1]보도매체!$A:$C,2,FALSE), "") -> 09_지방일간지 | M43: =IFERROR(VLOOKUP(I43,[1]보도매체!$A:$C,3,FALSE), "") -> 1.5 | N43: 45877
A44: 43 | B44: 8_국립축산과학원 | C44: =#REF! -> #REF! | D44: 2_축산자원개발부 | E44: 2_낙농과 | F44: 박성민 | G44: 즉시52 | H44: 국산 ‘로봇착유기’ 대만 수출···세계시장 진출 발판 | I44: 전북도민일보 | J44: 45876 | K44: 6 | L44: =IFERROR(VLOOKUP(I44,[1]보도매체!$A:$C,2,FALSE), "") -> 09_지방일간지 | M44: =IFERROR(VLOOKUP(I44,[1]보도매체!$A:$C,3,FALSE), "") -> 1.5 | N44: 45877
A45: 44 | B45: 8_국립축산과학원 | C45: =#REF! -> #REF! | D45: 2_축산자원개발부 | E45: 2_낙농과 | F45: 박성민 | G45: 즉시52 | H45: ‘국산 로봇착유기’ 대만 수출···세계 시장 진출 발판 | I45: 전라매일 | J45: 45876 | K45: 4 | L45: =IFERROR(VLOOKUP(I45,[1]보도매체!$A:$C,2,FALSE), "") -> 09_지방일간지 | M45: =IFERROR(VLOOKUP(I45,[1]보도매체!$A:$C,3,FALSE), "") -> 1.5 | N45: 45877
A46: 45 | B46: 8_국립축산과학원 | C46: =#REF! -> #REF! | D46: 2_축산자원개발부 | E46: 2_낙농과 | F46: 박성민 | G46: 즉시52 | H46: ‘국산 로봇착유기’ 대만 수출···세계 시장 진출 발판 | I46: 새전북신문 | J46: 45876 | K46: 4 | L46: =IFERROR(VLOOKUP(I46,[1]보도매체!$A:$C,2,FALSE), "") -> 09_지방일간지 | M46: =IFERROR(VLOOKUP(I46,[1]보도매체!$A:$C,3,FALSE), "") -> 1.5 | N46: 45877
A47: 46 | B47: 8_국립축산과학원 | C47: =#REF! -> #REF! | D47: 2_축산자원개발부 | E47: 2_낙농과 | F47: 박성민 | G47: 즉시52 | H47: ‘국산 로봇착유기’ 대만 수출···세계 시장 진출 발판 | I47: 전주매일 | J47: 45876 | K47: 6 | L47: =IFERROR(VLOOKUP(I47,[1]보도매체!$A:$C,2,FALSE), "") -> 09_지방일간지 | M47: =IFERROR(VLOOKUP(I47,[1]보도매체!$A:$C,3,FALSE), "") -> 1.5 | N47: 45877
A48: 47 | B48: 8_국립축산과학원 | C48: =#REF! -> #REF! | D48: 2_축산자원개발부 | E48: 2_낙농과 | F48: 박성민 | G48: 즉시52 | H48: 국산 로봇착유기 대만 수출···아시아 낙농시장 ‘교두보’ | I48: 전북일보 | J48: 45876 | K48: 6 | L48: =IFERROR(VLOOKUP(I48,[1]보도매체!$A:$C,2,FALSE), "") -> 09_지방일간지 | M48: =IFERROR(VLOOKUP(I48,[1]보도매체!$A:$C,3,FALSE), "") -> 1.5 | N48: 45877
A49: 48 | B49: 8_국립축산과학원 | C49: =#REF! -> #REF! | D49: 2_축산자원개발부 | E49: 4_조사료생산시스템과 | F49: 최보람 | G49: 즉시51 | H49: 창녕군, 사료피 신품종 현장 평가회 성료 | I49: 경남연합일보 | J49: 45876 | K49: 8 | L49: =IFERROR(VLOOKUP(I49,[1]보도매체!$A:$C,2,FALSE), "") -> 09_지방일간지 | M49: =IFERROR(VLOOKUP(I49,[1]보도매체!$A:$C,3,FALSE), "") -> 1.5 | N49: 45877
...

Sheet Sheet2
A3: 행 레이블
A4: 1_기획조정과
A5: 2_운영지원과
A6: 3_기술지원과
A7: 4_가축질병방역과
A8: 1_동물바이오공학과
A9: 2_동물유전체과
A10: 3_축산물이용과
A11: 4_축산환경과
A12: 5_영양생리팀
A13: 6_동물복지연구팀
A14: 1_가축개량평가과
... A22: 총합계

Sheet 양식
B2: 번호 | C2: 소속기관 | D2: 소속부 | E2: 소속부서 | F2: 구분
B3: 1 | C3: 8_국립축산과학원 | D3: 0_본원 | E3: 1_기획조정과
B4: 2 | C4: 8_국립축산과학원 | D4: 0_본원 | E4: 2_운영지원과
B5: 3 | C5: 8_국립축산과학원 | D5: 0_본원 | E5: 3_기술지원과
B6: 4 | C6: 8_국립축산과학원 | D6: 0_본원 | E6: 4_가축질병방역과
B7: 5 | C7: 8_국립축산과학원 | D7: 0_본원 | E7: 5_가축유전자원센터
B8: 6 | C8: 8_국립축산과학원 | D8: 0_본원 | E8: 6_한우연구소
B9: 7 | C9: 8_국립축산과학원 | D9: 0_본원 | E9: 7_가금연구소
B10: 8 | C10: 8_국립축산과학원 | D10: 0_본원 | E10: 8_난지축산연구소
B11: 9 | C11: 8_국립축산과학원 | D11: 1_축산생명환경부 | E11: 1_동물바이오공학과
B12: 10 | C12: 8_국립축산과학원 | D12: 1_축산생명환경부 | E12: 2_동물유전체과
B13: 11 | C13: 8_국립축산과학원 | D13: 1_축산생명환경부 | E13: 3_축산물이용과
B14: 12 | C14: 8_국립축산과학원 | D14: 1_축산생명환경부 | E14: 4_축산환경과
... B20: 18 | C20: 8_국립축산과학원 | D20: 2_축산자원개발부 | E20: 4_초지사료과
B21: 19
B22: 20
B23: 21
B24: 22
A26: 2019.04. 평가지표 번호 변동
B27: 01_TV-중앙
B28: 02_TV-지방 | C28: 02_TV-케이블중앙 | D28: 02_TV-종합편성채널
B29: 03_TV-케이블지방
B30: 04_기타(DMB,IPTV)
B31: 05_라디오-중앙
B32: 06_라디오-지방
B33: 07_중앙일간지
B34: 08_기타일간지 | C34: 08_스포츠신문
B35: 09_농업전문지 | C35: 09_지방일간지
B36: 10_월간지 | C36: 10_주간지 | D36: 10_무가지 | E36: 10_기타전문지 | F36: 10_기타월간지
B37: 11_기타(지역주간지)
B38: 12_대한민국 정책포털(korea.kr)
B39: 13_인터넷포털
B40: 14_해외홍보(TV,라디오,신문,잡지)
A41: 기고
B42: 15_중앙일간지
B43: 16_기타일간지 | C43: 16_스포츠신문
B44: 17_농업전문지 | C44: 17_지방일간지
B45: 18_월간지 | C45: 18_주간지 | D45: 18_무가지 | E45: 18_기타전문지 | F45: 18_기타월간지
B46: 19_기타(지역주간지)
B47: 20_대한민국 정책포털(korea.kr) 기고
...

Sheet 보도매체
A1: 보도매체 | B1: 구분 1 | C1: 구분 2(점수)
A2: 아주경제 | B2: 07_중앙일간지 | C2: 5
A3: 서울신문 | B3: 07_중앙일간지 | C3: 5
A4: 한겨레신문 | B4: 07_중앙일간지 | C4: 5
A5: 국민일보 | B5: 07_중앙일간지 | C5: 5
A6: 연합뉴스 | B6: 07_중앙일간지 | C6: 5
A7: 파이낸셜뉴스 | B7: 07_중앙일간지 | C7: 5
A8: 헤럴드경제 | B8: 07_중앙일간지 | C8: 5
A9: KBS 라디오 | B9: 05_라디오-중앙 | C9: 3
A10: SBS 라디오 | B10: 05_라디오-중앙 | C10: 3
A11: BBS 라디오 | B11: 05_라디오-중앙 | C11: 3
A12: 아시아타임즈 | B12: 08_기타일간지 | C12: 2
A13: 아시아일보 | B13: 08_기타일간지 | C13: 2
... A674: KPI뉴스 | B674: 13_인터넷포털 | C674: 0.1

Sheet 소속부서
A1: 소속부서 | B1: 소속부
A2: 1_기획조정과 | B2: 0_본원
A3: 2_운영지원과 | B3: 0_본원
A4: 3_기술지원과 | B4: 0_본원
A5: 4_가축질병방역과 | B5: 0_본원
A6: 5_가축유전자원센터 | B6: 0_본원
A7: 6_축산자원개발부이전추진팀 | B7: 0_본원
A8: 1_동물바이오유전체과 | B8: 1_축산생명환경부
A9: 2_동물유전체과 | B9: 1_축산생명환경부
A10: 3_축산푸드테크과 | B10: 1_축산생명환경부
A11: 4_스마트축산환경과 | B11: 1_축산생명환경부
A12: 5_가축정밀영양과 | B12: 1_축산생명환경부
... A20: 7_난지축산연구센터 | B20: 2_축산자원개발부
