Workbook

Sheet 2022년 누적시트
A1: 번호 | B1: 소속기관 | C1: 소속부서(복사) | D1: 소속부 | E1: 소속부서 | F1: 담당자 | G1: 보도관련 | H1: 제 목 | I1: 보도매체 | J1: 게재일 | K1: 면 | L1: 구분 1 | M1: 구분 2(점수) | N1: 스크랩일
A2: 1 | B2: 8_국립축산과학원 | C2: =E2 -> 4_조사료생산시스템과 | D2: 2_축산자원개발부 | E2: 4_조사료생산시스템과 | F2: 박형수 | G2: 보도자료81 | H2: 국립축산과학원, ‘사료피 신품종 현장 평가 및 수확 연시회’ 개최 | I2: 농축환경신문 | J2: 45880 | K2: 6 | L2: =IFERROR(VLOOKUP(I2,보도매체!$A:$C,2,FALSE), "") -> 09_농업전문지 | M2: =IFERROR(VLOOKUP(I2,보도매체!$A:$C,3,FALSE), "") -> 1.5
A3: 2 | B3: 8_국립축산과학원 | C3: =E3 -> 1_가축개량평가과 | D3: 2_축산자원개발부 | E3: 1_가축개량평가과 | F3: 성하승 | G3: 보도자료76 | H3: 농진청, ‘한우 교배계획 길라잡이 제38호’ 보급 시작 | I3: 농축환경신문 | J3: 45880 | K3: 6 | L3: =IFERROR(VLOOKUP(I3,보도매체!$A:$C,2,FALSE), "") -> 09_농업전문지 | M3: =IFERROR(VLOOKUP(I3,보도매체!$A:$C,3,FALSE), "") -> 1.5
A4: 3 | B4: 8_국립축산과학원 | C4: =E4 -> 3_축산푸드테크과 | D4: 1_축산생명환경부 | E4: 3_축산푸드테크과 | F4: 강선문 | G4: 보도자료78 | H4: 영양 풍부 여름철 보양식 고단백·저지방 칼슘 풍부 체력보강·기력 회복 효과 | I4: 축산경제신문 | J4: 45887 | K4: 4 | L4: =IFERROR(VLOOKUP(I4,보도매체!$A:$C,2,FALSE), "") -> 09_농업전문지 | M4: =IFERROR(VLOOKUP(I4,보도매체!$A:$C,3,FALSE), "") -> 1.5
A5: 4 | B5: 8_국립축산과학원 | C5: =E5 -> 1_가축개량평가과 | D5: =IFERROR(VLOOKUP(C5,소속부서!$A$2:$B$20,2,FALSE), "") -> 2_축산자원개발부 | E5: 1_가축개량평가과 | F5: 박병호 | H5: 한우 유전체 분석 사업 현장과 함께 개량 가속 | I5: 축산경제신문 | J5: 45887 | K5: 1 | L5: =IFERROR(VLOOKUP(I5,보도매체!$A:$C,2,FALSE), "") -> 09_농업전문지 | M5: =IFERROR(VLOOKUP(I5,보도매체!$A:$C,3,FALSE), "") -> 1.5
A6: 5 | B6: 8_국립축산과학원 | C6: =E6 -> 5_가축유전자원센터 | D6: 0_본원 | E6: 5_가축유전자원센터 | F6: 김승창 | G6: 즉시53 | H6: 축과원, ‘가축 유전자 검사 국제 인증’ 받아 | I6: 농축유통신문 | J6: 45889 | L6: =IFERROR(VLOOKUP(I6,보도매체!$A:$C,2,FALSE), "") -> 09_농업전문지 | M6: =IFERROR(VLOOKUP(I6,보도매체!$A:$C,3,FALSE), "") -> 1.5
A7: 6 | B7: 8_국립축산과학원 | C7: =E7 -> 5_가축유전자원센터 | D7: 0_본원 | E7: 5_가축유전자원센터 | F7: 김승창 | G7: 즉시53 | H7: 축과원 가축유전자원센터, 국내 첫 DNA 공인시험기관으로 인정 | I7: 농민신문 | J7: 45890 | L7: =IFERROR(VLOOKUP(I7,보도매체!$A:$C,2,FALSE), "") -> 09_농업전문지 | M7: =IFERROR(VLOOKUP(I7,보도매체!$A:$C,3,FALSE), "") -> 1.5
A8: 7 | B8: 8_국립축산과학원 | C8: =E8 -> 6_동물복지과 | D8: 1_축산생명환경부 | E8: 6_동물복지과 | F8: 김찬호 | G8: 보도자료80 | H8: 가축더위지수 연동 제어 기술, 산란계 보호 효과 ‘톡톡’ | I8: 농축유통신문 | J8: 45890 | L8: =IFERROR(VLOOKUP(I8,보도매체!$A:$C,2,FALSE), "") -> 09_농업전문지 | M8: =IFERROR(VLOOKUP(I8,보도매체!$A:$C,3,FALSE), "") -> 1.5
A9: 8 | B9: 8_국립축산과학원 | C9: =E9 -> 5_가축정밀영양과 | D9: 1_축산생명환경부 | E9: 5_가축정밀영양과 | F9: 강환구 | G9: 즉시54 | H9: 농진청, 사료산업 발전 기술협력 강화 | I9: 농축유통신문 | J9: 45890 | L9: =IFERROR(VLOOKUP(I9,보도매체!$A:$C,2,FALSE), "") -> 09_농업전문지 | M9: =IFERROR(VLOOKUP(I9,보도매체!$A:$C,3,FALSE), "") -> 1.5
A10: 9 | B10: 8_국립축산과학원 | C10: =E10 -> 3_축산푸드테크과 | D10: =IFERROR(VLOOKUP(C10,소속부서!$A$2:$B$20,2,FALSE), "") -> 1_축산생명환경부 | E10: 3_축산푸드테크과 | F10: 강선문 | H10: 2025년 한우 수출액 25억...시장 넓힌다 [농어촌이 미래다-그린 라이프] | I10: 세계일보 | J10: 45891 | L10: =IFERROR(VLOOKUP(I10,보도매체!$A:$C,2,FALSE), "") -> 07_중앙일간지 | M10: =IFERROR(VLOOKUP(I10,보도매체!$A:$C,3,FALSE), "") -> 5
A11: 10 | B11: 8_국립축산과학원 | C11: =E11 -> 2_낙농과 | D11: 2_축산자원개발부 | E11: 2_낙농과 | F11: 박성민 | G11: 즉시52 | H11: ‘국산 로봇착유기’ 대만 수출···세계 시장 진출 발판 | I11: 한국농기자재산업 | J11: 45885 | K11: 11 | L11: =IFERROR(VLOOKUP(I11,보도매체!$A:$C,2,FALSE), "") -> 09_농업전문지 | M11: =IFERROR(VLOOKUP(I11,보도매체!$A:$C,3,FALSE), "") -> 1.5
A12: 11 | B12: 8_국립축산과학원 | C12: =E12 -> 4_조사료생산시스템과 | D12: 2_축산자원개발부 | E12: 4_조사료생산시스템과 | F12: 고하늘 | H12: 경주시, 외동 건초생산 사업장 개소···연간 5천톤 자급 체계 구축 | I12: 검찰연합일보 | J12: 45774 | L12: =IFERROR(VLOOKUP(I12,보도매체!$A:$C,2,FALSE), "") -> 13_인터넷포털 | M12: =IFERROR(VLOOKUP(I12,보도매체!$A:$C,3,FALSE), "") -> 0.1
A13: 12 | B13: 8_국립축산과학원 | C13: =E13 -> 3_기술지원과 | D13: =IFERROR(VLOOKUP(C13,소속부서!$A$2:$B$20,2,FALSE), "") -> 0_본원 | E13: 3_기술지원과 | F13: 이경은 | H13: 국립축산과학원, 연천군 한우농가 축사로 사용자 교육 실시 | I13: 검찰연합일보 | J13: 45776 | L13: =IFERROR(VLOOKUP(I13,보도매체!$A:$C,2,FALSE), "") -> 13_인터넷포털 | M13: =IFERROR(VLOOKUP(I13,보도매체!$A:$C,3,FALSE), "") -> 0.1
A14: 13 | B14: 8_국립축산과학원 | C14: =E14 -> 3_기술지원과 | D14: 0_본원 | E14: 3_기술지원과 | F14: 이승인 | G14: 보도자료42 | H14: 농촌진흥청, 2025년도 가축인공수정사 면허시험 시행계획 공고 | I14: 검찰연합일보 | J14: 45778 | L14: =IFERROR(VLOOKUP(I14,보도매체!$A:$C,2,FALSE), "") -> 13_인터넷포털 | M14: =IFERROR(VLOOKUP(I14,보도매체!$A:$C,3,FALSE), "") -> 0.1
A15: 14 | B15: 8_국립축산과학원 | C15: =E15 -> 2_운영지원과 | D15: 0_본원 | E15: 2_운영지원과 | F15: 전승일 | H15: 청송군, 산불 피해농고 일손돕기 적극 추진 | I15: 검찰연합일보 | J15: 45783 | L15: =IFERROR(VLOOKUP(I15,보도매체!$A:$C,2,FALSE), "") -> 13_인터넷포털 | M15: =IFERROR(VLOOKUP(I15,보도매체!$A:$C,3,FALSE), "") -> 0.1
A16: 15 | B16: 8_국립축산과학원 | C16: =E16 -> 4_조사료생산시스템과 | D16: 2_축산자원개발부 | E16: 4_조사료생산시스템과 | F16: 박형수 | G16: 보도자료81 | H16: 농촌진흥청, 논 재배용 사료피 신품종 ‘조온’·‘다온’ 개발 | I16: 검찰연합일보 | J16: 45790 | L16: =IFERROR(VLOOKUP(I16,보도매체!$A:$C,2,FALSE), "") -> 13_인터넷포털 | M16: =IFERROR(VLOOKUP(I16,보도매체!$A:$C,3,FALSE), "") -> 0.1
A17: 16 | B17: 8_국립축산과학원 | C17: =E17 -> 5_가축정밀영양과 | D17: 1_축산생명환경부 | E17: 5_가축정밀영양과 | F17: 이성신 | G17: 보도자료46 | H17: 농촌진흥청, 저메탄 사료 소재 개발 탄소중립 축산 실현 ‘첫걸음’ | I17: 검찰연합일보 | J17: 45792 | L17: =IFERROR(VLOOKUP(I17,보도매체!$A:$C,2,FALSE), "") -> 13_인터넷포털 | M17: =IFERROR(VLOOKUP(I17,보도매체!$A:$C,3,FALSE), "") -> 0.1
A18: 17 | B18: 8_국립축산과학원 | C18: =E18 -> 4_스마트축산환경과 | D18: =IFERROR(VLOOKUP(C18,소속부서!$A$2:$B$20,2,FALSE), "") -> 1_축산생명환경부 | E18: 4_스마트축산환경과 | F18: 김병현 | G18: 보도자료47 | H18: 농촌진흥청, 무더위 성큼 축사 냉방·환기시설 미리 점검하세요 | I18: 검찰연합일보 | J18: 45793 | L18: =IFERROR(VLOOKUP(I18,보도매체!$A:$C,2,FALSE), "") -> 13_인터넷포털 | M18: =IFERROR(VLOOKUP(I18,보도매체!$A:$C,3,FALSE), "") -> 0.1
A19: 18 | B19: 8_국립축산과학원 | C19: =E19 -> 7_난지축산연구센터 | D19: =IFERROR(VLOOKUP(C19,소속부서!$A$2:$B$20,2,FALSE), "") -> 2_축산자원개발부 | E19: 7_난지축산연구센터 | F19: 조인철 | G19: 즉시26 | H19: 경상남도농업기술원,‘난축맛돈’ 육지 상륙! 새로운 도전이 시작된다 | I19: 검찰연합일보 | J19: 45798 | L19: =IFERROR(VLOOKUP(I19,보도매체!$A:$C,2,FALSE), "") -> 13_인터넷포털 | M19: =IFERROR(VLOOKUP(I19,보도매체!$A:$C,3,FALSE), "") -> 0.1
A20: 19 | B20: 8_국립축산과학원 | C20: =E20 -> 2_낙농과 | D20: 2_축산자원개발부 | E20: 2_낙농과 | F20: 이지환 | H20: 임실군, 임실N치즈 프리미엄화 발판 마련 | I20: 검찰연합일보 | J20: 45803 | L20: =IFERROR(VLOOKUP(I20,보도매체!$A:$C,2,FALSE), "") -> 13_인터넷포털 | M20: =IFERROR(VLOOKUP(I20,보도매체!$A:$C,3,FALSE), "") -> 0.1
A21: 20 | B21: 8_국립축산과학원 | D21: 0_본원 | E21: 3_기술지원과 | F21: 김정현 | G21: 보도자료49 | H21: 농촌진흥청, 폭염 속 가축 건강 챙긴다···축종별 대응 요령은? | I21: 검찰연합일보 | J21: 45805 | L21: =IFERROR(VLOOKUP(I21,보도매체!$A:$C,2,FALSE), "") -> 13_인터넷포털 | M21: =IFERROR(VLOOKUP(I21,보도매체!$A:$C,3,FALSE), "") -> 0.1
A22: 21 | B22: 8_국립축산과학원 | D22: 2_축산자원개발부 | E22: 2_낙농과 | F22: 허태영 | G22: 보도자료50 | H22: 농촌진흥청, 폭염 속 가축 건강 챙긴다···축종별 대응 요령은? | I22: 검찰연합일보 | J22: 45805 | L22: =IFERROR(VLOOKUP(I22,보도매체!$A:$C,2,FALSE), "") -> 13_인터넷포털 | M22: =IFERROR(VLOOKUP(I22,보도매체!$A:$C,3,FALSE), "") -> 0.1
A23: 22 | B23: 8_국립축산과학원 | D23: 2_축산자원개발부 | E23: 3_양돈과 | F23: 김조은 | G23: 보도자료51 | H23: 농촌진흥청, 폭염 속 가축 건강 챙긴다···축종별 대응 요령은? | I23: 검찰연합일보 | J23: 45805 | L23: =IFERROR(VLOOKUP(I23,보도매체!$A:$C,2,FALSE), "") -> 13_인터넷포털 | M23: =IFERROR(VLOOKUP(I23,보도매체!$A:$C,3,FALSE), "") -> 0.1
A24: 23 | B24: 8_국립축산과학원 | C24: =E24 -> 6_가금연구센터 | D24: 2_축산자원개발부 | E24: 6_가금연구센터 | F24: 홍의철 | G24: 보도자료52 | H24: 농촌진흥청, 폭염 속 가축 건강 챙긴다···축종별 대응 요령은? | I24: 검찰연합일보 | J24: 45805 | L24: =IFERROR(VLOOKUP(I24,보도매체!$A:$C,2,FALSE), "") -> 13_인터넷포털 | M24: =IFERROR(VLOOKUP(I24,보도매체!$A:$C,3,FALSE), "") -> 0.1
A25: 24 | B25: 8_국립축산과학원 | C25: =E25 -> 4_스마트축산환경과 | D25: 1_축산생명환경부 | E25: 4_스마트축산환경과 | F25: 이동준 | H25: 전북자치도, 고질 악취에 정책 중심 종합대책 가동 | I25: 검찰연합일보 | J25: 45805 | L25: =IFERROR(VLOOKUP(I25,보도매체!$A:$C,2,FALSE), "") -> 13_인터넷포털 | M25: =IFERROR(VLOOKUP(I25,보도매체!$A:$C,3,FALSE), "") -> 0.1
A26: 25 | B26: 8_국립축산과학원 | C26: =E26 -> 4_조사료생산시스템과 | D26: 2_축산자원개발부 | E26: 4_조사료생산시스템과 | F26: 우제훈 | G26: 즉시31 | H26: 농촌진흥청, 국가대표 풀사료 ‘이탈리안 라이그라스’ 씨앗부터 건초까지 전 과정 국산 기술로 완성 | I26: 검찰연합일보 | J26: 45806 | L26: =IFERROR(VLOOKUP(I26,보도매체!$A:$C,2,FALSE), "") -> 13_인터넷포털 | M26: =IFERROR(VLOOKUP(I26,보도매체!$A:$C,3,FALSE), "") -> 0.1
A27: 26 | B27: 8_국립축산과학원 | C27: =E27 -> 4_스마트축산환경과 | D27: 1_축산생명환경부 | E27: 4_스마트축산환경과 | F27: 이동준 | G27: 보도자료54 | H27: 농촌진흥청, 고체연료용 가축분뇨 축사 내 3개월 저장이 가장 적절 | I27: 검찰연합일보 | J27: 45807 | L27: =IFERROR(VLOOKUP(I27,보도매체!$A:$C,2,FALSE), "") -> 13_인터넷포털 | M27: =IFERROR(VLOOKUP(I27,보도매체!$A:$C,3,FALSE), "") -> 0.1
A28: 27 | B28: 8_국립축산과학원 | C28: =E28 -> 4_조사료생산시스템과 | D28: 2_축산자원개발부 | E28: 4_조사료생산시스템과 | F28: 정종성 | H28: 고성군, 알팔파 생산 시스템 구축 | I28: 검찰연합일보 | J28: 45807 | L28: =IFERROR(VLOOKUP(I28,보도매체!$A:$C,2,FALSE), "") -> 13_인터넷포털 | M28: =IFERROR(VLOOKUP(I28,보도매체!$A:$C,3,FALSE), "") -> 0.1
A29: 28 | B29: 8_국립축산과학원 | C29: =E29 -> 3_기술지원과 | D29: 0_본원 | E29: 3_기술지원과 | F29: 이승인 | G29: 보도자료56 | H29: 농촌진흥청, 스마트 축산농장 기록관리 경연대회 참가자 모집 | I29: 검찰연합일보 | J29: 45810 | L29: =IFERROR(VLOOKUP(I29,보도매체!$A:$C,2,FALSE), "") -> 13_인터넷포털 | M29: =IFERROR(VLOOKUP(I29,보도매체!$A:$C,3,FALSE), "") -> 0.1
A30: 29 | B30: 8_국립축산과학원 | C30: =E30 -> 4_조사료생산시스템과 | D30: 2_축산자원개발부 | E30: 4_조사료생산시스템과 | F30: 고하늘 | G30: 보도자료57 | H30: 농촌진흥청, 여름 장마 대비 사료작물 안정 생산 조건은? | I30: 검찰연합일보 | J30: 45812 | L30: =IFERROR(VLOOKUP(I30,보도매체!$A:$C,2,FALSE), "") -> 13_인터넷포털 | M30: =IFERROR(VLOOKUP(I30,보도매체!$A:$C,3,FALSE), "") -> 0.1
A31: 30 | B31: 8_국립축산과학원 | C31: =E31 -> 6_축산자원개발부이전추진팀 | D31: =IFERROR(VLOOKUP(C31,소속부서!$A$2:$B$20,2,FALSE), "") -> 0_본원 | E31: 6_축산자원개발부이전추진팀 | F31: 임은아 | H31: 천안 축산자원개발부 이전·국가산단 유치기념탑 준공 | I31: 검찰연합일보 | J31: 45817 | L31: =IFERROR(VLOOKUP(I31,보도매체!$A:$C,2,FALSE), "") -> 13_인터넷포털 | M31: =IFERROR(VLOOKUP(I31,보도매체!$A:$C,3,FALSE), "") -> 0.1
A32: 31 | B32: 8_국립축산과학원 | C32: =E32 -> 4_스마트축산환경과 | D32: 1_축산생명환경부 | E32: 4_스마트축산환경과 | F32: 장동화 | G32: 보도자료58 | H32: 농촌진흥청, 여름철 축사 화재·정전 피해 각별하게 주의해야 | I32: 검찰연합일보 | J32: 45818 | L32: =IFERROR(VLOOKUP(I32,보도매체!$A:$C,2,FALSE), "") -> 13_인터넷포털 | M32: =IFERROR(VLOOKUP(I32,보도매체!$A:$C,3,FALSE), "") -> 0.1
A33: 32 | B33: 8_국립축산과학원 | C33: =E33 -> 3_기술지원과 | D33: =IFERROR(VLOOKUP(C33,소속부서!$A$2:$B$20,2,FALSE), "") -> 0_본원 | E33: 3_기술지원과 | F33: 이경은 | H33: “한우농가 살리자”···정읍시, 전문가 컨설팅으로 맞춤형 지원 | I33: 검찰연합일보 | J33: 45819 | L33: =IFERROR(VLOOKUP(I33,보도매체!$A:$C,2,FALSE), "") -> 13_인터넷포털 | M33: =IFERROR(VLOOKUP(I33,보도매체!$A:$C,3,FALSE), "") -> 0.1
A34: 33 | B34: 8_국립축산과학원 | C34: =E34 -> 3_기술지원과 | D34: =IFERROR(VLOOKUP(C34,소속부서!$A$2:$B$20,2,FALSE), "") -> 0_본원 | E34: 3_기술지원과 | F34: 김창한 | H34: [청년농부] ‘갓 짜낸 우유’만...10년째 지켜온 청년농부의 고집 | I34: YTN | J34: 45893 | L34: =IFERROR(VLOOKUP(I34,보도매체!$A:$C,2,FALSE), "") -> 02_TV-케이블중앙 | M34: =IFERROR(VLOOKUP(I34,보도매체!$A:$C,3,FALSE), "") -> 4
A35: 34 | B35: 8_국립축산과학원 | C35: =E35 -> 5_가축유전자원센터 | D35: 0_본원 | E35: 5_가축유전자원센터 | F35: 김관우 | H35: 염소 신품종 육종 위해 해외 생축 반입 늘어나야 | I35: 농수축산신문 | J35: 45891 | K35: 12 | L35: =IFERROR(VLOOKUP(I35,보도매체!$A:$C,2,FALSE), "") -> 09_농업전문지 | M35: =IFERROR(VLOOKUP(I35,보도매체!$A:$C,3,FALSE), "") -> 1.5
A36: 35 | B36: 8_국립축산과학원 | C36: =E36 -> 6_동물복지과 | D36: 1_축산생명환경부 | E36: 6_동물복지과 | F36: 김찬호 | G36: 보도자료80 | H36: 가축더위지수 연동 자동제어 기술, 산란계 폐사율 감소 | I36: 농수축산신문 | J36: 45891 | K36: 14 | L36: =IFERROR(VLOOKUP(I36,보도매체!$A:$C,2,FALSE), "") -> 09_농업전문지 | M36: =IFERROR(VLOOKUP(I36,보도매체!$A:$C,3,FALSE), "") -> 1.5
A37: 36 | B37: 8_국립축산과학원 | C37: =E37 -> 6_동물복지과 | D37: 1_축산생명환경부 | E37: 6_동물복지과 | F37: 김찬호 | G37: 보도자료80 | H37: 가축더위지수 자동제어 기술, 산란계 보호 효과 입증 | I37: 축산신문 | J37: 45891 | K37: 9 | L37: =IFERROR(VLOOKUP(I37,보도매체!$A:$C,2,FALSE), "") -> 09_농업전문지 | M37: =IFERROR(VLOOKUP(I37,보도매체!$A:$C,3,FALSE), "") -> 1.5
A38: 37 | B38: 8_국립축산과학원 | C38: =E38 -> 5_가축유전자원센터 | D38: 0_본원 | E38: 5_가축유전자원센터 | F38: 김승창 | G38: 즉시53 | H38: 가축 유전자 검사 국제 인증 획득 | I38: 축산신문 | J38: 45891 | K38: 3 | L38: =IFERROR(VLOOKUP(I38,보도매체!$A:$C,2,FALSE), "") -> 09_농업전문지 | M38: =IFERROR(VLOOKUP(I38,보도매체!$A:$C,3,FALSE), "") -> 1.5
A39: 38 | B39: 8_국립축산과학원 | C39: =E39 -> 6_동물복지과 | D39: 1_축산생명환경부 | E39: 6_동물복지과 | F39: 김찬호 | G39: 보도자료80 | H39: ‘이 지수’ 따라 냉수 자동공급···‘산란계’ 고온스트레스 잡는다 | I39: 농민신문 | J39: 45891 | L39: =IFERROR(VLOOKUP(I39,보도매체!$A:$C,2,FALSE), "") -> 09_농업전문지 | M39: =IFERROR(VLOOKUP(I39,보도매체!$A:$C,3,FALSE), "") -> 1.5
A40: 39 | B40: 8_국립축산과학원 | C40: =E40 -> 5_가축유전자원센터 | D40: 0_본원 | E40: 5_가축유전자원센터 | F40: 김승창 | G40: 즉시53 | H40: 축산원, 가축유전정보 검사기관 등록 | I40: 축산경제신문 | J40: 45891 | L40: =IFERROR(VLOOKUP(I40,보도매체!$A:$C,2,FALSE), "") -> 09_농업전문지 | M40: =IFERROR(VLOOKUP(I40,보도매체!$A:$C,3,FALSE), "") -> 1.5
...

Sheet Sheet2
A3: 행 레이블
A4: 1_기획조정과
A5: 2_운영지원과
A6: 3_기술지원과
A7: 4_가축질병방역과
A8: 1_동물바이오공학과
A9: 2_동물유전체과
A10: 3_축산물이용과
A11: 4_축산환경과
A12: 5_영양생리팀
A13: 6_동물복지연구팀
A14: 1_가축개량평가과
... A22: 총합계

Sheet 양식
B2: 번호 | C2: 소속기관 | D2: 소속부 | E2: 소속부서 | F2: 구분
B3: 1 | C3: 8_국립축산과학원 | D3: 0_본원 | E3: 1_기획조정과
B4: 2 | C4: 8_국립축산과학원 | D4: 0_본원 | E4: 2_운영지원과
B5: 3 | C5: 8_국립축산과학원 | D5: 0_본원 | E5: 3_기술지원과
B6: 4 | C6: 8_국립축산과학원 | D6: 0_본원 | E6: 4_가축질병방역과
B7: 5 | C7: 8_국립축산과학원 | D7: 0_본원 | E7: 5_가축유전자원센터
B8: 6 | C8: 8_국립축산과학원 | D8: 0_본원 | E8: 6_한우연구소
B9: 7 | C9: 8_국립축산과학원 | D9: 0_본원 | E9: 7_가금연구소
B10: 8 | C10: 8_국립축산과학원 | D10: 0_본원 | E10: 8_난지축산연구소
B11: 9 | C11: 8_국립축산과학원 | D11: 1_축산생명환경부 | E11: 1_동물바이오공학과
B12: 10 | C12: 8_국립축산과학원 | D12: 1_축산생명환경부 | E12: 2_동물유전체과
B13: 11 | C13: 8_국립축산과학원 | D13: 1_축산생명환경부 | E13: 3_축산물이용과
B14: 12 | C14: 8_국립축산과학원 | D14: 1_축산생명환경부 | E14: 4_축산환경과
... B20: 18 | C20: 8_국립축산과학원 | D20: 2_축산자원개발부 | E20: 4_초지사료과
B21: 19
B22: 20
B23: 21
B24: 22
A26: 2019.04. 평가지표 번호 변동
B27: 01_TV-중앙
B28: 02_TV-지방 | C28: 02_TV-케이블중앙 | D28: 02_TV-종합편성채널
B29: 03_TV-케이블지방
B30: 04_기타(DMB,IPTV)
B31: 05_라디오-중앙
B32: 06_라디오-지방
B33: 07_중앙일간지
B34: 08_기타일간지 | C34: 08_스포츠신문
B35: 09_농업전문지 | C35: 09_지방일간지
B36: 10_월간지 | C36: 10_주간지 | D36: 10_무가지 | E36: 10_기타전문지 | F36: 10_기타월간지
B37: 11_기타(지역주간지)
B38: 12_대한민국 정책포털(korea.kr)
B39: 13_인터넷포털
B40: 14_해외홍보(TV,라디오,신문,잡지)
A41: 기고
B42: 15_중앙일간지
B43: 16_기타일간지 | C43: 16_스포츠신문
B44: 17_농업전문지 | C44: 17_지방일간지
B45: 18_월간지 | C45: 18_주간지 | D45: 18_무가지 | E45: 18_기타전문지 | F45: 18_기타월간지
B46: 19_기타(지역주간지)
B47: 20_대한민국 정책포털(korea.kr) 기고
...

Sheet 보도매체
A1: 보도매체 | B1: 구분 1 | C1: 구분 2(점수)
A2: 아주경제 | B2: 07_중앙일간지 | C2: 5
A3: 서울신문 | B3: 07_중앙일간지 | C3: 5
A4: 한겨레신문 | B4: 07_중앙일간지 | C4: 5
A5: 국민일보 | B5: 07_중앙일간지 | C5: 5
A6: 연합뉴스 | B6: 07_중앙일간지 | C6: 5
A7: 파이낸셜뉴스 | B7: 07_중앙일간지 | C7: 5
A8: 헤럴드경제 | B8: 07_중앙일간지 | C8: 5
A9: KBS 라디오 | B9: 05_라디오-중앙 | C9: 3
A10: SBS 라디오 | B10: 05_라디오-중앙 | C10: 3
A11: BBS 라디오 | B11: 05_라디오-중앙 | C11: 3
A12: 아시아타임즈 | B12: 08_기타일간지 | C12: 2
A13: 아시아일보 | B13: 08_기타일간지 | C13: 2
... A676: 뉴스후플러스 | B676: 13_인터넷포털 | C676: 0.1

Sheet 소속부서
A1: 소속부서 | B1: 소속부
A2: 1_기획조정과 | B2: 0_본원
A3: 2_운영지원과 | B3: 0_본원
A4: 3_기술지원과 | B4: 0_본원
A5: 4_가축질병방역과 | B5: 0_본원
A6: 5_가축유전자원센터 | B6: 0_본원
A7: 6_축산자원개발부이전추진팀 | B7: 0_본원
A8: 1_동물바이오유전체과 | B8: 1_축산생명환경부
A9: 2_동물유전체과 | B9: 1_축산생명환경부
A10: 3_축산푸드테크과 | B10: 1_축산생명환경부
A11: 4_스마트축산환경과 | B11: 1_축산생명환경부
A12: 5_가축정밀영양과 | B12: 1_축산생명환경부
... A20: 7_난지축산연구센터 | B20: 2_축산자원개발부
